Traceback (most recent call last):
  File "/Users/admin/.virtualenvs/Rubikloud/bin/luigid", line 11, in <module>
    load_entry_point('luigi==2.8.7', 'console_scripts', 'luigid')()
  File "/Users/admin/.virtualenvs/Rubikloud/lib/python3.7/site-packages/luigi/cmdline.py", line 35, in luigid
    logdir=opts.logdir, unix_socket=opts.unix_socket)
  File "/Users/admin/.virtualenvs/Rubikloud/lib/python3.7/site-packages/luigi/process.py", line 127, in daemonize
    cmd(api_port=api_port, address=address, unix_socket=unix_socket)
  File "/Users/admin/.virtualenvs/Rubikloud/lib/python3.7/site-packages/luigi/server.py", line 336, in run
    unix_socket=unix_socket,
  File "/Users/admin/.virtualenvs/Rubikloud/lib/python3.7/site-packages/luigi/server.py", line 314, in _init_api
    api_sockets = tornado.netutil.bind_sockets(api_port, address=address)
  File "/Users/admin/.virtualenvs/Rubikloud/lib/python3.7/site-packages/tornado/netutil.py", line 197, in bind_sockets
    sock.bind(sockaddr)
OSError: [Errno 48] Address already in use
Traceback (most recent call last):
  File "/Users/admin/.virtualenvs/Rubikloud/bin/luigid", line 11, in <module>
    load_entry_point('luigi==2.8.7', 'console_scripts', 'luigid')()
  File "/Users/admin/.virtualenvs/Rubikloud/lib/python3.7/site-packages/luigi/cmdline.py", line 35, in luigid
    logdir=opts.logdir, unix_socket=opts.unix_socket)
  File "/Users/admin/.virtualenvs/Rubikloud/lib/python3.7/site-packages/luigi/process.py", line 127, in daemonize
    cmd(api_port=api_port, address=address, unix_socket=unix_socket)
  File "/Users/admin/.virtualenvs/Rubikloud/lib/python3.7/site-packages/luigi/server.py", line 336, in run
    unix_socket=unix_socket,
  File "/Users/admin/.virtualenvs/Rubikloud/lib/python3.7/site-packages/luigi/server.py", line 314, in _init_api
    api_sockets = tornado.netutil.bind_sockets(api_port, address=address)
  File "/Users/admin/.virtualenvs/Rubikloud/lib/python3.7/site-packages/tornado/netutil.py", line 197, in bind_sockets
    sock.bind(sockaddr)
OSError: [Errno 48] Address already in use
Traceback (most recent call last):
  File "/Users/admin/.virtualenvs/Rubikloud/bin/luigid", line 11, in <module>
    load_entry_point('luigi==2.8.7', 'console_scripts', 'luigid')()
  File "/Users/admin/.virtualenvs/Rubikloud/lib/python3.7/site-packages/luigi/cmdline.py", line 35, in luigid
    logdir=opts.logdir, unix_socket=opts.unix_socket)
  File "/Users/admin/.virtualenvs/Rubikloud/lib/python3.7/site-packages/luigi/process.py", line 127, in daemonize
    cmd(api_port=api_port, address=address, unix_socket=unix_socket)
  File "/Users/admin/.virtualenvs/Rubikloud/lib/python3.7/site-packages/luigi/server.py", line 336, in run
    unix_socket=unix_socket,
  File "/Users/admin/.virtualenvs/Rubikloud/lib/python3.7/site-packages/luigi/server.py", line 314, in _init_api
    api_sockets = tornado.netutil.bind_sockets(api_port, address=address)
  File "/Users/admin/.virtualenvs/Rubikloud/lib/python3.7/site-packages/tornado/netutil.py", line 197, in bind_sockets
    sock.bind(sockaddr)
OSError: [Errno 48] Address already in use
Traceback (most recent call last):
  File "/Users/admin/.virtualenvs/Rubikloud/bin/luigid", line 11, in <module>
    load_entry_point('luigi==2.8.7', 'console_scripts', 'luigid')()
  File "/Users/admin/.virtualenvs/Rubikloud/lib/python3.7/site-packages/luigi/cmdline.py", line 35, in luigid
    logdir=opts.logdir, unix_socket=opts.unix_socket)
  File "/Users/admin/.virtualenvs/Rubikloud/lib/python3.7/site-packages/luigi/process.py", line 127, in daemonize
    cmd(api_port=api_port, address=address, unix_socket=unix_socket)
  File "/Users/admin/.virtualenvs/Rubikloud/lib/python3.7/site-packages/luigi/server.py", line 336, in run
    unix_socket=unix_socket,
  File "/Users/admin/.virtualenvs/Rubikloud/lib/python3.7/site-packages/luigi/server.py", line 314, in _init_api
    api_sockets = tornado.netutil.bind_sockets(api_port, address=address)
  File "/Users/admin/.virtualenvs/Rubikloud/lib/python3.7/site-packages/tornado/netutil.py", line 197, in bind_sockets
    sock.bind(sockaddr)
OSError: [Errno 48] Address already in use
Traceback (most recent call last):
  File "/Users/admin/.virtualenvs/Rubikloud/bin/luigid", line 11, in <module>
    load_entry_point('luigi==2.8.7', 'console_scripts', 'luigid')()
  File "/Users/admin/.virtualenvs/Rubikloud/lib/python3.7/site-packages/luigi/cmdline.py", line 35, in luigid
    logdir=opts.logdir, unix_socket=opts.unix_socket)
  File "/Users/admin/.virtualenvs/Rubikloud/lib/python3.7/site-packages/luigi/process.py", line 127, in daemonize
    cmd(api_port=api_port, address=address, unix_socket=unix_socket)
  File "/Users/admin/.virtualenvs/Rubikloud/lib/python3.7/site-packages/luigi/server.py", line 336, in run
    unix_socket=unix_socket,
  File "/Users/admin/.virtualenvs/Rubikloud/lib/python3.7/site-packages/luigi/server.py", line 314, in _init_api
    api_sockets = tornado.netutil.bind_sockets(api_port, address=address)
  File "/Users/admin/.virtualenvs/Rubikloud/lib/python3.7/site-packages/tornado/netutil.py", line 197, in bind_sockets
    sock.bind(sockaddr)
OSError: [Errno 48] Address already in use
Traceback (most recent call last):
  File "/Users/admin/.virtualenvs/Rubikloud/bin/luigid", line 11, in <module>
    load_entry_point('luigi==2.8.7', 'console_scripts', 'luigid')()
  File "/Users/admin/.virtualenvs/Rubikloud/lib/python3.7/site-packages/luigi/cmdline.py", line 35, in luigid
    logdir=opts.logdir, unix_socket=opts.unix_socket)
  File "/Users/admin/.virtualenvs/Rubikloud/lib/python3.7/site-packages/luigi/process.py", line 127, in daemonize
    cmd(api_port=api_port, address=address, unix_socket=unix_socket)
  File "/Users/admin/.virtualenvs/Rubikloud/lib/python3.7/site-packages/luigi/server.py", line 336, in run
    unix_socket=unix_socket,
  File "/Users/admin/.virtualenvs/Rubikloud/lib/python3.7/site-packages/luigi/server.py", line 314, in _init_api
    api_sockets = tornado.netutil.bind_sockets(api_port, address=address)
  File "/Users/admin/.virtualenvs/Rubikloud/lib/python3.7/site-packages/tornado/netutil.py", line 197, in bind_sockets
    sock.bind(sockaddr)
OSError: [Errno 48] Address already in use
Traceback (most recent call last):
  File "/Users/admin/.virtualenvs/Rubikloud/bin/luigid", line 11, in <module>
    load_entry_point('luigi==2.8.7', 'console_scripts', 'luigid')()
  File "/Users/admin/.virtualenvs/Rubikloud/lib/python3.7/site-packages/luigi/cmdline.py", line 35, in luigid
    logdir=opts.logdir, unix_socket=opts.unix_socket)
  File "/Users/admin/.virtualenvs/Rubikloud/lib/python3.7/site-packages/luigi/process.py", line 127, in daemonize
    cmd(api_port=api_port, address=address, unix_socket=unix_socket)
  File "/Users/admin/.virtualenvs/Rubikloud/lib/python3.7/site-packages/luigi/server.py", line 336, in run
    unix_socket=unix_socket,
  File "/Users/admin/.virtualenvs/Rubikloud/lib/python3.7/site-packages/luigi/server.py", line 314, in _init_api
    api_sockets = tornado.netutil.bind_sockets(api_port, address=address)
  File "/Users/admin/.virtualenvs/Rubikloud/lib/python3.7/site-packages/tornado/netutil.py", line 197, in bind_sockets
    sock.bind(sockaddr)
OSError: [Errno 48] Address already in use
Traceback (most recent call last):
  File "/Users/admin/.virtualenvs/Rubikloud/bin/luigid", line 11, in <module>
    load_entry_point('luigi==2.8.7', 'console_scripts', 'luigid')()
  File "/Users/admin/.virtualenvs/Rubikloud/lib/python3.7/site-packages/luigi/cmdline.py", line 35, in luigid
    logdir=opts.logdir, unix_socket=opts.unix_socket)
  File "/Users/admin/.virtualenvs/Rubikloud/lib/python3.7/site-packages/luigi/process.py", line 127, in daemonize
    cmd(api_port=api_port, address=address, unix_socket=unix_socket)
  File "/Users/admin/.virtualenvs/Rubikloud/lib/python3.7/site-packages/luigi/server.py", line 336, in run
    unix_socket=unix_socket,
  File "/Users/admin/.virtualenvs/Rubikloud/lib/python3.7/site-packages/luigi/server.py", line 314, in _init_api
    api_sockets = tornado.netutil.bind_sockets(api_port, address=address)
  File "/Users/admin/.virtualenvs/Rubikloud/lib/python3.7/site-packages/tornado/netutil.py", line 197, in bind_sockets
    sock.bind(sockaddr)
OSError: [Errno 48] Address already in use
Traceback (most recent call last):
  File "/Users/admin/.virtualenvs/Rubikloud/bin/luigid", line 11, in <module>
    load_entry_point('luigi==2.8.7', 'console_scripts', 'luigid')()
  File "/Users/admin/.virtualenvs/Rubikloud/lib/python3.7/site-packages/luigi/cmdline.py", line 35, in luigid
    logdir=opts.logdir, unix_socket=opts.unix_socket)
  File "/Users/admin/.virtualenvs/Rubikloud/lib/python3.7/site-packages/luigi/process.py", line 127, in daemonize
    cmd(api_port=api_port, address=address, unix_socket=unix_socket)
  File "/Users/admin/.virtualenvs/Rubikloud/lib/python3.7/site-packages/luigi/server.py", line 336, in run
    unix_socket=unix_socket,
  File "/Users/admin/.virtualenvs/Rubikloud/lib/python3.7/site-packages/luigi/server.py", line 314, in _init_api
    api_sockets = tornado.netutil.bind_sockets(api_port, address=address)
  File "/Users/admin/.virtualenvs/Rubikloud/lib/python3.7/site-packages/tornado/netutil.py", line 197, in bind_sockets
    sock.bind(sockaddr)
OSError: [Errno 48] Address already in use
Traceback (most recent call last):
  File "/Users/admin/.virtualenvs/Rubikloud/bin/luigid", line 11, in <module>
    load_entry_point('luigi==2.8.7', 'console_scripts', 'luigid')()
  File "/Users/admin/.virtualenvs/Rubikloud/lib/python3.7/site-packages/luigi/cmdline.py", line 35, in luigid
    logdir=opts.logdir, unix_socket=opts.unix_socket)
  File "/Users/admin/.virtualenvs/Rubikloud/lib/python3.7/site-packages/luigi/process.py", line 127, in daemonize
    cmd(api_port=api_port, address=address, unix_socket=unix_socket)
  File "/Users/admin/.virtualenvs/Rubikloud/lib/python3.7/site-packages/luigi/server.py", line 336, in run
    unix_socket=unix_socket,
  File "/Users/admin/.virtualenvs/Rubikloud/lib/python3.7/site-packages/luigi/server.py", line 314, in _init_api
    api_sockets = tornado.netutil.bind_sockets(api_port, address=address)
  File "/Users/admin/.virtualenvs/Rubikloud/lib/python3.7/site-packages/tornado/netutil.py", line 197, in bind_sockets
    sock.bind(sockaddr)
OSError: [Errno 48] Address already in use
Traceback (most recent call last):
  File "/Users/admin/.virtualenvs/Rubikloud/bin/luigid", line 11, in <module>
    load_entry_point('luigi==2.8.7', 'console_scripts', 'luigid')()
  File "/Users/admin/.virtualenvs/Rubikloud/lib/python3.7/site-packages/luigi/cmdline.py", line 35, in luigid
    logdir=opts.logdir, unix_socket=opts.unix_socket)
  File "/Users/admin/.virtualenvs/Rubikloud/lib/python3.7/site-packages/luigi/process.py", line 127, in daemonize
    cmd(api_port=api_port, address=address, unix_socket=unix_socket)
  File "/Users/admin/.virtualenvs/Rubikloud/lib/python3.7/site-packages/luigi/server.py", line 336, in run
    unix_socket=unix_socket,
  File "/Users/admin/.virtualenvs/Rubikloud/lib/python3.7/site-packages/luigi/server.py", line 314, in _init_api
    api_sockets = tornado.netutil.bind_sockets(api_port, address=address)
  File "/Users/admin/.virtualenvs/Rubikloud/lib/python3.7/site-packages/tornado/netutil.py", line 197, in bind_sockets
    sock.bind(sockaddr)
OSError: [Errno 48] Address already in use
Traceback (most recent call last):
  File "/Users/admin/.virtualenvs/Rubikloud/bin/luigid", line 11, in <module>
    load_entry_point('luigi==2.8.7', 'console_scripts', 'luigid')()
  File "/Users/admin/.virtualenvs/Rubikloud/lib/python3.7/site-packages/luigi/cmdline.py", line 35, in luigid
    logdir=opts.logdir, unix_socket=opts.unix_socket)
  File "/Users/admin/.virtualenvs/Rubikloud/lib/python3.7/site-packages/luigi/process.py", line 127, in daemonize
    cmd(api_port=api_port, address=address, unix_socket=unix_socket)
  File "/Users/admin/.virtualenvs/Rubikloud/lib/python3.7/site-packages/luigi/server.py", line 336, in run
    unix_socket=unix_socket,
  File "/Users/admin/.virtualenvs/Rubikloud/lib/python3.7/site-packages/luigi/server.py", line 314, in _init_api
    api_sockets = tornado.netutil.bind_sockets(api_port, address=address)
  File "/Users/admin/.virtualenvs/Rubikloud/lib/python3.7/site-packages/tornado/netutil.py", line 197, in bind_sockets
    sock.bind(sockaddr)
OSError: [Errno 48] Address already in use
Traceback (most recent call last):
  File "/Users/admin/.virtualenvs/Rubikloud/bin/luigid", line 11, in <module>
    load_entry_point('luigi==2.8.7', 'console_scripts', 'luigid')()
  File "/Users/admin/.virtualenvs/Rubikloud/lib/python3.7/site-packages/luigi/cmdline.py", line 35, in luigid
    logdir=opts.logdir, unix_socket=opts.unix_socket)
  File "/Users/admin/.virtualenvs/Rubikloud/lib/python3.7/site-packages/luigi/process.py", line 127, in daemonize
    cmd(api_port=api_port, address=address, unix_socket=unix_socket)
  File "/Users/admin/.virtualenvs/Rubikloud/lib/python3.7/site-packages/luigi/server.py", line 336, in run
    unix_socket=unix_socket,
  File "/Users/admin/.virtualenvs/Rubikloud/lib/python3.7/site-packages/luigi/server.py", line 314, in _init_api
    api_sockets = tornado.netutil.bind_sockets(api_port, address=address)
  File "/Users/admin/.virtualenvs/Rubikloud/lib/python3.7/site-packages/tornado/netutil.py", line 197, in bind_sockets
    sock.bind(sockaddr)
OSError: [Errno 48] Address already in use
Traceback (most recent call last):
  File "/Users/admin/.virtualenvs/Rubikloud/bin/luigid", line 11, in <module>
    load_entry_point('luigi==2.8.7', 'console_scripts', 'luigid')()
  File "/Users/admin/.virtualenvs/Rubikloud/lib/python3.7/site-packages/luigi/cmdline.py", line 35, in luigid
    logdir=opts.logdir, unix_socket=opts.unix_socket)
  File "/Users/admin/.virtualenvs/Rubikloud/lib/python3.7/site-packages/luigi/process.py", line 127, in daemonize
    cmd(api_port=api_port, address=address, unix_socket=unix_socket)
  File "/Users/admin/.virtualenvs/Rubikloud/lib/python3.7/site-packages/luigi/server.py", line 336, in run
    unix_socket=unix_socket,
  File "/Users/admin/.virtualenvs/Rubikloud/lib/python3.7/site-packages/luigi/server.py", line 314, in _init_api
    api_sockets = tornado.netutil.bind_sockets(api_port, address=address)
  File "/Users/admin/.virtualenvs/Rubikloud/lib/python3.7/site-packages/tornado/netutil.py", line 197, in bind_sockets
    sock.bind(sockaddr)
OSError: [Errno 48] Address already in use
Traceback (most recent call last):
  File "/Users/admin/.virtualenvs/Rubikloud/bin/luigid", line 11, in <module>
    load_entry_point('luigi==2.8.7', 'console_scripts', 'luigid')()
  File "/Users/admin/.virtualenvs/Rubikloud/lib/python3.7/site-packages/luigi/cmdline.py", line 35, in luigid
    logdir=opts.logdir, unix_socket=opts.unix_socket)
  File "/Users/admin/.virtualenvs/Rubikloud/lib/python3.7/site-packages/luigi/process.py", line 127, in daemonize
    cmd(api_port=api_port, address=address, unix_socket=unix_socket)
  File "/Users/admin/.virtualenvs/Rubikloud/lib/python3.7/site-packages/luigi/server.py", line 336, in run
    unix_socket=unix_socket,
  File "/Users/admin/.virtualenvs/Rubikloud/lib/python3.7/site-packages/luigi/server.py", line 314, in _init_api
    api_sockets = tornado.netutil.bind_sockets(api_port, address=address)
  File "/Users/admin/.virtualenvs/Rubikloud/lib/python3.7/site-packages/tornado/netutil.py", line 197, in bind_sockets
    sock.bind(sockaddr)
OSError: [Errno 48] Address already in use
